<?xml version="1.0" encoding="utf-8"?>
<!-- =================================================================================== -->
<!-- |    This document is a hand edited version of the output autogenerated by xacro  | -->
<!-- |    from panda_arm.urdf.xacro.  It features the following changes:               | -->
<!-- |      1) Lacrosse ball end effector on a stick, matching the physical end        | -->
<!-- |         effector used for the C3 experiments.                                   | -->
<!-- |      2) No collision geometry except for the ball end effector.                 | -->
<!-- |      3) Offset between a "worldfixed" link and Franka link 0 that matches the   | -->
<!-- |         measured height offset between the toss surface and Franka bottom plane | -->
<!-- |         in the robot interaction dataset.  The toss surface in PLL is always    | -->
<!-- |         assumed to be at z=0.                                                   | -->
<!-- =================================================================================== -->
<robot xmlns:drake="http://drake.mit.edu" name="panda">
    <!-- PLL looks for any links named 'worldfixed' and fixes them to the world
    with identity tranformation between them. -->
    <link name="worldfixed" />
    <link name="panda_link0">
        <inertial>
            <mass value="2.92"/>
            <origin xyz="-0.025566 -2.88e-05 0.057332" rpy="0 0 0"/>
            <inertia ixx="0.00782229414331" ixy="-1.56191622996e-05" ixz="-0.00126005738123" iyy="0.0109027971813" iyz="1.08233858202e-05" izz="0.0102355503949"/>
        </inertial>
        <visual>
            <origin rpy="1.57079632679 0 0"/>
            <geometry>
                <mesh filename="package://drake_models/franka_description/meshes/visual/link0.obj"/>
            </geometry>
        </visual>
        <!-- <collision>
            <origin rpy="0 0 0" xyz="0.02 0.0 0.04"/>
            <geometry>
                <sphere radius="0.06"/>
            </geometry>
        </collision> -->
        <!-- <collision>
            <origin rpy="0 0 0" xyz="0.01 0.05 0.06"/>
            <geometry>
                <sphere radius="0.06"/>
            </geometry>
        </collision> -->
        <!-- <collision>
            <origin rpy="0 0 0" xyz="0.01 -0.05 0.06"/>
            <geometry>
                <sphere radius="0.06"/>
            </geometry>
        </collision> -->
        <!-- <collision>
            <origin rpy="0 0 0" xyz="-0.06 0.0 0.06"/>
            <geometry>
                <sphere radius="0.06"/>
            </geometry>
        </collision> -->
        <!-- <collision>
            <origin rpy="0 0 0" xyz="-0.06 0.05 0.06"/>
            <geometry>
                <sphere radius="0.06"/>
            </geometry>
        </collision> -->
        <!-- <collision>
            <origin rpy="0 0 0" xyz="-0.03 0.05 0.06"/>
            <geometry>
                <sphere radius="0.06"/>
            </geometry>
        </collision> -->
        <!-- <collision>
            <origin rpy="0 0 0" xyz="-0.03 -0.05 0.06"/>
            <geometry>
                <sphere radius="0.06"/>
            </geometry>
        </collision> -->
        <!-- <collision>
            <origin rpy="0 0 0" xyz="-0.06 -0.05 0.06"/>
            <geometry>
                <sphere radius="0.06"/>
            </geometry>
        </collision> -->
        <!-- <collision>
            <origin rpy="0 0 0" xyz="-0.09 -0.05 0.06"/>
            <geometry>
                <sphere radius="0.06"/>
            </geometry>
        </collision> -->
        <!-- <collision>
            <origin rpy="0 0 0" xyz="-0.09 0.0 0.06"/>
            <geometry>
                <sphere radius="0.06"/>
            </geometry>
        </collision> -->
        <!-- <collision>
            <origin rpy="0 0 0" xyz="-0.09 0.05 0.06"/>
            <geometry>
                <sphere radius="0.06"/>
            </geometry>
        </collision> -->
        <!-- <collision>
            <origin rpy="0 0 0" xyz="-0.12 0.0 0.06"/>
            <geometry>
                <sphere radius="0.06"/>
            </geometry>
        </collision> -->
        <!-- <collision>
            <origin rpy="0 0 0" xyz="0.0 0.0 0.113"/>
            <geometry>
                <sphere radius="0.06"/>
            </geometry>
        </collision> -->
        <!-- <collision>
            <origin rpy="0 0 0" xyz="0.0 0.0 0.083"/>
            <geometry>
                <sphere radius="0.06"/>
            </geometry>
        </collision> -->
    </link>
    <!-- This joint establishes the location of the Franka wrt a z=0 toss
    surface.  The xy offset should be 0, and the z offset was measured to be the
    Franka is approximately 8.7mm higher than the toss surface. -->
    <joint name="fixed_franka" type="fixed">
        <origin rpy="0 0 0" xyz="0 0 0.0087"/>
        <parent link="worldfixed"/>
        <child link="panda_link0"/>
    </joint>

    <link name="panda_link1">
        <inertial>
            <mass value="2.74"/>
            <origin xyz="0 -0.0324958 -0.0675818" rpy="0 0 0"/>
            <inertia ixx="0.0180416958283" ixy="0.0" ixz="0.0" iyy="0.0159136071891" iyz="0.0046758424612" izz="0.00620690827127"/>
        </inertial>
        <visual>
            <origin rpy="1.57079632679 0 0"/>
            <geometry>
                <mesh filename="package://drake_models/franka_description/meshes/visual/link1.obj"/>
            </geometry>
        </visual>
        <!-- <collision>
            <origin rpy="0 0 0" xyz="0.0 0.0 -0.13"/>
            <geometry>
                <sphere radius="0.06"/>
            </geometry>
        </collision> -->
        <!-- <collision>
            <origin rpy="0 0 0" xyz="0.0 0.0 -0.16"/>
            <geometry>
                <sphere radius="0.06"/>
            </geometry>
        </collision> -->
        <!-- <collision>
            <origin rpy="0 0 0" xyz="0.0 0.0 -0.19"/>
            <geometry>
                <sphere radius="0.06"/>
            </geometry>
        </collision> -->
        <!-- <collision>
            <origin rpy="0 0 0" xyz="0.0 -0.04 -0.06"/>
            <geometry>
                <sphere radius="0.06"/>
            </geometry>
        </collision> -->
        <!-- <collision>
            <origin rpy="0 0 0" xyz="0.0 -0.0750 -0.0"/>
            <geometry>
                <sphere radius="0.06"/>
            </geometry>
        </collision> -->
        <!-- <collision>
            <origin rpy="0 0 0" xyz="0.0 -0.0350 -0.0"/>
            <geometry>
                <sphere radius="0.06"/>
            </geometry>
        </collision> -->
    </link>
    <joint name="panda_joint1" type="revolute">
        <origin rpy="0 0 0" xyz="0 0 0.333"/>
        <parent link="panda_link0"/>
        <child link="panda_link1"/>
        <axis xyz="0 0 1"/>
        <limit effort="87" lower="-2.8973" upper="2.8973" velocity="2.1750"/>
    </joint>
    <link name="panda_link2">
        <inertial>
            <mass value="2.74"/>
            <origin xyz="0 -0.06861 0.0322285" rpy="0 0 0"/>
            <inertia ixx="0.0182856182281" ixy="0.0" ixz="0.0" iyy="0.00621358421175" iyz="-0.00472844221905" izz="0.0161514346309"/>
        </inertial>
        <visual>
            <origin rpy="1.57079632679 0 0"/>
            <geometry>
                <mesh filename="package://drake_models/franka_description/meshes/visual/link2.obj"/>
            </geometry>
        </visual>
        <!-- <collision>
            <origin rpy="0 0 0" xyz="0.0 0.0 0.0"/>
            <geometry>
                <sphere radius="0.06"/>
            </geometry>
        </collision> -->
        <!-- <collision>
            <origin rpy="0 0 0" xyz="0.0 0.0 0.035"/>
            <geometry>
                <sphere radius="0.06"/>
            </geometry>
        </collision> -->
        <!-- <collision>
            <origin rpy="0 0 0" xyz="0.0 0.0 0.075"/>
            <geometry>
                <sphere radius="0.06"/>
            </geometry>
        </collision> -->
        <!-- <collision>
            <origin rpy="0 0 0" xyz="0.0 -0.1710 0.0"/>
            <geometry>
                <sphere radius="0.06"/>
            </geometry>
        </collision> -->
        <!-- <collision>
            <origin rpy="0 0 0" xyz="0.0 -0.1360 0.0"/>
            <geometry>
                <sphere radius="0.06"/>
            </geometry>
        </collision> -->
        <!-- <collision>
            <origin rpy="0 0 0" xyz="0.0 -0.070 0.040"/>
            <geometry>
                <sphere radius="0.06"/>
            </geometry>
        </collision> -->
    </link>
    <joint name="panda_joint2" type="revolute">
        <origin rpy="-1.57079632679 0 0" xyz="0 0 0"/>
        <parent link="panda_link1"/>
        <child link="panda_link2"/>
        <axis xyz="0 0 1"/>
        <limit effort="87" lower="-1.7628" upper="1.7628" velocity="2.1750"/>
    </joint>
    <link name="panda_link3">
        <inertial>
            <mass value="2.38"/>
            <origin xyz="0.0469893 0.0316374 -0.031704" rpy="0 0 0"/>
            <inertia ixx="0.00771376630908" ixy="-0.00248490625138" ixz="-0.00332147581033" iyy="0.00989108008727" iyz="-0.00217796151484" izz="0.00811723558464"/>
        </inertial>
        <visual>
            <origin rpy="1.57079632679 0 0"/>
            <geometry>
                <mesh filename="package://drake_models/franka_description/meshes/visual/link3.obj"/>
            </geometry>
        </visual>
        <!-- <collision>
            <origin rpy="0 0 0" xyz="0.0 0.0 -0.11"/>
            <geometry>
                <sphere radius="0.06"/>
            </geometry>
        </collision> -->
        <!-- <collision>
            <origin rpy="0 0 0" xyz="0.0 0.0 -0.07"/>
            <geometry>
                <sphere radius="0.06"/>
            </geometry>
        </collision> -->
        <!-- <collision>
            <origin rpy="0 0 0" xyz="0.0825 0.03 -0.0"/>
            <geometry>
                <sphere radius="0.06"/>
            </geometry>
        </collision> -->
        <!-- <collision>
            <origin rpy="0 0 0" xyz="0.0825 0.06 -0.0"/>
            <geometry>
                <sphere radius="0.06"/>
            </geometry>
        </collision> -->
        <!-- <collision>
            <origin rpy="0 0 0" xyz="0.04 0.03 -0.03"/>
            <geometry>
                <sphere radius="0.06"/>
            </geometry>
        </collision> -->
    </link>
    <joint name="panda_joint3" type="revolute">
        <origin rpy="1.57079632679 0 0" xyz="0 -0.316 0"/>
        <parent link="panda_link2"/>
        <child link="panda_link3"/>
        <axis xyz="0 0 1"/>
        <limit effort="87" lower="-2.8973" upper="2.8973" velocity="2.1750"/>
    </joint>
    <link name="panda_link4">
        <inertial>
            <mass value="2.38"/>
            <origin xyz="-0.0360446 0.0336853 0.031882" rpy="0 0 0"/>
            <inertia ixx="0.00799663881132" ixy="0.00347095570217" ixz="-0.00241222942995" iyy="0.00825390705278" iyz="0.00235774044121" izz="0.0102515004345"/>
        </inertial>
        <visual>
            <origin rpy="1.57079632679 0 0"/>
            <geometry>
                <mesh filename="package://drake_models/franka_description/meshes/visual/link4.obj"/>
            </geometry>
        </visual>
        <!-- <collision>
            <origin rpy="0 0 0" xyz="0.0 0.0 0.06"/>
            <geometry>
                <sphere radius="0.06"/>
            </geometry>
        </collision> -->
        <!-- <collision>
            <origin rpy="0 0 0" xyz="0.0 0.0 0.03"/>
            <geometry>
                <sphere radius="0.06"/>
            </geometry>
        </collision> -->
        <!-- <collision>
            <origin rpy="0 0 0" xyz="-0.0350 0.03 0.04"/>
            <geometry>
                <sphere radius="0.05"/>
            </geometry>
        </collision> -->
        <!-- <collision>
            <origin rpy="0 0 0" xyz="-0.05 0.04 0.01"/>
            <geometry>
                <sphere radius="0.055"/>
            </geometry>
        </collision> -->
        <!-- <collision>
            <origin rpy="0 0 0" xyz="0.0 0.0 0.0"/>
            <geometry>
                <sphere radius="0.06"/>
            </geometry>
        </collision> -->
        <!-- <collision>
            <origin rpy="0 0 0" xyz="-0.0825 0.0640 -0.0"/>
            <geometry>
                <sphere radius="0.06"/>
            </geometry>
        </collision> -->
        <!-- <collision>
            <origin rpy="0 0 0" xyz="-0.0825 0.1040 -0.0"/>
            <geometry>
                <sphere radius="0.06"/>
            </geometry>
        </collision> -->
    </link>
    <joint name="panda_joint4" type="revolute">
        <origin rpy="1.57079632679 0 0" xyz="0.0825 0 0"/>
        <parent link="panda_link3"/>
        <child link="panda_link4"/>
        <axis xyz="0 0 1"/>
        <limit effort="87" lower="-3.0718" upper="-0.0698" velocity="2.1750"/>
    </joint>
    <link name="panda_link5">
        <inertial>
            <mass value="2.74"/>
            <origin xyz="0 0.0610427 -0.104176" rpy="0 0 0"/>
            <inertia ixx="0.030371374513" ixy="6.50283587108e-07" ixz="-1.05129179916e-05" iyy="0.0288752887402" iyz="-0.00775653445787" izz="0.00444134056164"/>
        </inertial>
        <visual>
            <origin rpy="1.57079632679 0 0"/>
            <geometry>
                <mesh filename="package://drake_models/franka_description/meshes/visual/link5.obj"/>
            </geometry>
        </visual>
        <!-- <collision>
            <origin rpy="0 0 0" xyz="0.0 0.0 -0.24"/>
            <geometry>
                <sphere radius="0.06"/>
            </geometry>
        </collision> -->
        <!-- <collision>
            <origin rpy="0 0 0" xyz="0.0 0.0 -0.21"/>
            <geometry>
                <sphere radius="0.06"/>
            </geometry>
        </collision> -->
        <!-- <collision>
            <origin rpy="0 0 0" xyz="0.0 0.09 -0.055"/>
            <geometry>
                <sphere radius="0.035"/>
            </geometry>
        </collision> -->
        <!-- <collision>
            <origin rpy="0 0 0" xyz="0.0 0.0850 -0.08"/>
            <geometry>
                <sphere radius="0.035"/>
            </geometry>
        </collision> -->
        <!-- <collision>
            <origin rpy="0 0 0" xyz="0.0 0.0850 -0.11"/>
            <geometry>
                <sphere radius="0.035"/>
            </geometry>
        </collision> -->
        <!-- <collision>
            <origin rpy="0 0 0" xyz="0.0 0.08 -0.13"/>
            <geometry>
                <sphere radius="0.035"/>
            </geometry>
        </collision> -->
        <!-- <collision>
            <origin rpy="0 0 0" xyz="0.0 0.08 -0.15"/>
            <geometry>
                <sphere radius="0.035"/>
            </geometry>
        </collision> -->
        <!-- <collision>
            <origin rpy="0 0 0" xyz="0.0 0.07 -0.16"/>
            <geometry>
                <sphere radius="0.04"/>
            </geometry>
        </collision> -->
        <!-- <collision>
            <origin rpy="0 0 0" xyz="0.0 0.08 -0.02"/>
            <geometry>
                <sphere radius="0.05"/>
            </geometry>
        </collision> -->
        <!-- <collision>
            <origin rpy="0 0 0" xyz="0.0 0.08 -0.0"/>
            <geometry>
                <sphere radius="0.055"/>
            </geometry>
        </collision> -->
        <!-- <collision>
            <origin rpy="0 0 0" xyz="0.0 0.05 -0.20"/>
            <geometry>
                <sphere radius="0.055"/>
            </geometry>
        </collision> -->
        <!-- <collision>
            <origin rpy="0 0 0" xyz="0.0 0.07 -0.0"/>
            <geometry>
                <sphere radius="0.06"/>
            </geometry>
        </collision> -->
    </link>
    <joint name="panda_joint5" type="revolute">
        <origin rpy="-1.57079632679 0 0" xyz="-0.0825 0.384 0"/>
        <parent link="panda_link4"/>
        <child link="panda_link5"/>
        <axis xyz="0 0 1"/>
        <limit effort="12" lower="-2.8973" upper="2.8973" velocity="2.610"/>
    </joint>
    <link name="panda_link6">
        <inertial>
            <mass value="1.55"/>
            <origin xyz="0.0510509 0.009108 0.0106343" rpy="0 0 0"/>
            <inertia ixx="0.00303336450376" ixy="-0.000437276865508" ixz="0.000629257294877" iyy="0.00404479911567" iyz="0.000130472021025" izz="0.00558234286039"/>
        </inertial>
        <visual>
            <origin rpy="1.57079632679 0 0"/>
            <geometry>
                <mesh filename="package://drake_models/franka_description/meshes/visual/link6.obj"/>
            </geometry>
        </visual>
        <!-- <collision>
            <origin rpy="0 0 0" xyz="0.08 0.03 0.0"/>
            <geometry>
                <sphere radius="0.06"/>
            </geometry>
        </collision> -->
        <!-- <collision>
            <origin rpy="0 0 0" xyz="0.04 0.01 0.0"/>
            <geometry>
                <sphere radius="0.06"/>
            </geometry>
        </collision> -->
        <!-- <collision>
            <origin rpy="0 0 0" xyz="0.04 0.0 0.0"/>
            <geometry>
                <sphere radius="0.06"/>
            </geometry>
        </collision> -->
        <!-- <collision>
            <origin rpy="0 0 0" xyz="0.0 0.0 0.01"/>
            <geometry>
                <sphere radius="0.06"/>
            </geometry>
        </collision> -->
        <!-- <collision>
            <origin rpy="0 0 0" xyz="0.0 0.0 -0.03"/>
            <geometry>
                <sphere radius="0.05"/>
            </geometry>
        </collision> -->
    </link>
    <joint name="panda_joint6" type="revolute">
        <origin rpy="1.57079632679 0 0" xyz="0 0 0"/>
        <parent link="panda_link5"/>
        <child link="panda_link6"/>
        <axis xyz="0 0 1"/>
        <limit effort="12" lower="-0.0175" upper="3.7525" velocity="2.610"/>
    </joint>
    <link name="panda_link7">
        <inertial>
            <mass value="0.54"/>
            <origin xyz="0.0109695 0.0107965 0.0650411" rpy="0 0 0"/>
            <inertia ixx="0.000888868887021" ixy="-0.00012239074652" ixz="3.98699829666e-05" iyy="0.000888001373233" iyz="-9.33825115206e-05" izz="0.0007176834609"/>
        </inertial>
        <visual>
            <origin rpy="1.57079632679 0 0"/>
            <geometry>
                <mesh filename="package://drake_models/franka_description/meshes/visual/link7.obj"/>
            </geometry>
        </visual>
        <!-- <collision>
            <origin rpy="0 0 0" xyz="0 0 0.06"/>
            <geometry>
                <sphere radius="0.06"/>
            </geometry>
        </collision> -->
        <!-- <collision>
            <origin rpy="0 0 0" xyz="0 0 0.01"/>
            <geometry>
                <sphere radius="0.05"/>
            </geometry>
        </collision> -->
    </link>
    <joint name="panda_joint7" type="revolute">
        <origin rpy="1.57079632679 0 0" xyz="0.088 0 0"/>
        <parent link="panda_link6"/>
        <child link="panda_link7"/>
        <axis xyz="0 0 1"/>
        <limit effort="12" lower="-2.8973" upper="2.8973" velocity="2.610"/>
    </joint>

    <transmission name="panda_tran1">
        <type>transmission_interface/SimpleTransmission</type>
        <joint name="panda_joint1">
            <hardwareInterface>PositionJointInterface</hardwareInterface>
        </joint>
        <actuator name="panda_motor1">
            <hardwareInterface>PositionJointInterface</hardwareInterface>
            <mechanicalReduction>1</mechanicalReduction>
        </actuator>
    </transmission>
    <transmission name="panda_tran2">
        <type>transmission_interface/SimpleTransmission</type>
        <joint name="panda_joint2">
            <hardwareInterface>PositionJointInterface</hardwareInterface>
        </joint>
        <actuator name="panda_motor2">
            <hardwareInterface>PositionJointInterface</hardwareInterface>
            <mechanicalReduction>1</mechanicalReduction>
        </actuator>
    </transmission>
    <transmission name="panda_tran3">
        <type>transmission_interface/SimpleTransmission</type>
        <joint name="panda_joint3">
            <hardwareInterface>PositionJointInterface</hardwareInterface>
        </joint>
        <actuator name="panda_motor3">
            <hardwareInterface>PositionJointInterface</hardwareInterface>
            <mechanicalReduction>1</mechanicalReduction>
        </actuator>
    </transmission>
    <transmission name="panda_tran4">
        <type>transmission_interface/SimpleTransmission</type>
        <joint name="panda_joint4">
            <hardwareInterface>PositionJointInterface</hardwareInterface>
        </joint>
        <actuator name="panda_motor4">
            <hardwareInterface>PositionJointInterface</hardwareInterface>
            <mechanicalReduction>1</mechanicalReduction>
        </actuator>
    </transmission>
    <transmission name="panda_tran5">
        <type>transmission_interface/SimpleTransmission</type>
        <joint name="panda_joint5">
            <hardwareInterface>PositionJointInterface</hardwareInterface>
        </joint>
        <actuator name="panda_motor5">
            <hardwareInterface>PositionJointInterface</hardwareInterface>
            <mechanicalReduction>1</mechanicalReduction>
        </actuator>
    </transmission>
    <transmission name="panda_tran6">
        <type>transmission_interface/SimpleTransmission</type>
        <joint name="panda_joint6">
            <hardwareInterface>PositionJointInterface</hardwareInterface>
        </joint>
        <actuator name="panda_motor6">
            <hardwareInterface>PositionJointInterface</hardwareInterface>
            <mechanicalReduction>1</mechanicalReduction>
        </actuator>
    </transmission>
    <transmission name="panda_tran7">
        <type>transmission_interface/SimpleTransmission</type>
        <joint name="panda_joint7">
            <hardwareInterface>PositionJointInterface</hardwareInterface>
        </joint>
        <actuator name="panda_motor7">
            <hardwareInterface>PositionJointInterface</hardwareInterface>
            <mechanicalReduction>1</mechanicalReduction>
        </actuator>
    </transmission>

    <!-- No need to keep collision filter group since these links have no
    collision geometries. -->
    <!-- <drake:collision_filter_group name="group_link57">
        <drake:member link="panda_link5"/>
        <drake:member link="panda_link7"/>
        <drake:ignored_collision_filter_group name="group_link57"/>
    </drake:collision_filter_group> -->

    <!-- End effector -->
    <material name="black">
        <color rgba="0.3 0.3 0.3 1"/>
    </material>
    <link name="end_effector_base">
        <inertial>
            <origin rpy="0 0 0" xyz="0 0 -0.0048"/>
            <mass value="0.0779312"/>
            <inertia
                ixx="1.9930319916000003e-05"
                iyy="1.9930319916000003e-05"
                izz="3.866361660000001e-05"
                ixy="0" ixz="0" iyz="0"/>
        </inertial>
        <!-- <collision>
            <origin rpy="0 0 0" xyz="0 0 -0.0048"/>
            <geometry>
                    <cylinder radius="0.0315" length="0.0096"/>
            </geometry>
        </collision> -->
        <visual>
            <origin rpy="0 0 0" xyz="0 0 -0.0048"/>
            <geometry>
                <cylinder radius="0.0315" length="0.0096"/>
            </geometry>
        </visual>
    </link>
    <link name="end_effector_link">
        <inertial>
            <origin rpy="0 0 0" xyz="0 0 -0.0508"/>
            <mass value="0.1340688"/>
            <inertia
                ixx="0.00012073375853199997"
                iyy="0.00012073375853199997"
                izz="1.0811978376e-05"
                ixy="0" ixz="0" iyz="0"/>
        </inertial>
        <visual>
            <origin rpy="0 0 0" xyz="0 0 -0.0508"/>
            <geometry>
                <cylinder radius="0.0127" length="0.1016"/>
            </geometry>
        </visual>
    </link>
    <joint name="fix_link_base" type="fixed">
         <origin rpy="0 0 0" xyz="0 0 -0.0096"/>
         <parent link="end_effector_base"/>
         <child link="end_effector_link"/>
    </joint>
    <link name="end_effector_tip">
        <inertial>
            <origin rpy="0 0 0" xyz="0 0 0.0"/>
            <mass value="0.057"/>
            <inertia
                ixx="8.669700000000001e-06"
                iyy="8.669700000000001e-06"
                izz="8.669700000000001e-06"
                ixy="0" ixz="0" iyz="0"/>
        </inertial>
        <visual>
            <origin rpy="0 0 0" xyz="0 0 0"/>
            <geometry>
                <sphere radius="0.0195"/>
            </geometry>
            <material name="black"/>
        </visual>
        <collision>
            <origin rpy="0 0 0" xyz="0 0 0"/>
            <geometry>
                <sphere radius="0.0195"/>
            </geometry>
            <drake:proximity_properties>
                <drake:mu_static value="1"/>
                <drake:mu_dynamic value="1"/>
            </drake:proximity_properties>
        </collision>
    </link>
    <joint name="fix_tip_link" type="fixed">
        <origin rpy="0 0 0" xyz="0 0 -0.1169"/>
        <parent link="end_effector_link"/>
        <child link="end_effector_tip"/>
    </joint>
    <joint name="ee_to_franka" type="fixed">
        <origin rpy="3.14159265 0 0" xyz="0 0 0.107"/>
        <parent link="panda_link7"/>
        <child link="end_effector_base"/>
    </joint>

</robot>